Workbook

Sheet Dashboard
A1: ✈ FLIGHT SCHEDULE
A3: Origin: | B3: DEL | C3: =IFERROR(INDEX(Lists!$B:$B,MATCH($B3,Lists!$A:$A,0)),"") -> Delhi | E3: Destination: | G3: CJB | H3: =IFERROR(INDEX(Lists!$B:$B,MATCH($G3,Lists!$A:$A,0)),"") -> Coimbatore
A4: =IFERROR("Rates: IndiGo eff. "&TEXT('Flight Rates'!$X$4,"dd-mmm-yy")&" | Air India eff. "&TEXT('Flight Rates'!$X$6,"dd-mmm-yy")&" | Linked "&TEXT('Flight Rates'!$X$2,"dd-mmm-yy"),"Rates not linked yet - run link_rates.py") -> Rates: IndiGo eff. 16-Aug-26 | Air India eff. 20-Aug-26 | Linked 29-Sep-26
A5: ROUTE | E5: WEEKLY FLIGHTS | G5: FLIGHT COUNT | I5: STATUS
A6: =C3&" ("&$B$3&") → "&H3&" ("&$G$3&")" -> Delhi (DEL) → Coimbatore (CJB) | E6: =SUMIFS('Raw Data'!$N$2:$N$1680,'Raw Data'!$A$2:$A$1680,$B$3,'Raw Data'!$B$2:$B$1680,$G$3) -> 24 | G6: =COUNT('Raw Data'!$O$2:$O$1680) -> 4 | I6: =IF($B$3=$G$3,"SAME CITY",IF(E6=0,"NO SERVICE","ACTIVE")) -> ACTIVE
A8: =IF($I$6="SAME CITY","⚠ Please select two different cities as Origin and Destination.",IF($I$6="NO SERVICE","✈ No nonstop flights currently operate on this route. Please try a different Origin / Destination combination.",""))
A10: AIRLINE | B10: FLT NO. | C10: PRODUCT | D10: ETD | E10: CPKG (₹/kg)
E11: 45+ kg | F11: 100+ kg
A12: =IF($X12="","",INDEX('Raw Data'!$D:$D,$X12)) -> INDIGO | B12: =IF($X12="","",INDEX('Raw Data'!$E:$E,$X12)) -> 6E6804 | C12: =IF($X12="","",IF($Y12="","Not linked",IF(INDEX('Flight Rates'!$G:$G,$Y12)<>"",INDEX('Flight Rates'!$G:$G,$Y12),IF($Z12="NO TARIFF LOADED","No tariff","No rate")))) -> GCR | D12: =IF($X12="","",INDEX('Raw Data'!$F:$F,$X12)) -> 05:10 | E12: =IF($Y12="","",IF(INDEX('Flight Rates'!$K:$K,$Y12)="","",INDEX('Flight Rates'!$K:$K,$Y12)+N($T12)+N($U12))) -> 92 | F12: =IF($Y12="","",IF(INDEX('Flight Rates'!$L:$L,$Y12)="","",INDEX('Flight Rates'!$L:$L,$Y12)+N($T12)+N($U12))) -> 90 | T12: =IF($Y12="","",N(INDEX('Flight Rates'!$S:$S,$Y12))) -> 4 | U12: =IF(OR($Y12="",$C12="No tariff",$C12="No rate"),"",IFERROR(N(INDEX('Add-on Rates'!$C:$C,MATCH($A12,'Add-on Rates'!$A:$A,0))),0)) -> 18 | X12: =IFERROR(SMALL('Raw Data'!$O$2:$O$1680,1),"") -> 325 | Y12: =IF($X12="","",IFERROR(MATCH($B$3&"|"&$G$3&"|"&$B12&"|"&$D12,'Flight Rates'!$A:$A,0),"")) -> 300 | Z12: =IF($Y12="","",INDEX('Flight Rates'!$P:$P,$Y12)) -> OK
A13: =IF($X13="","",INDEX('Raw Data'!$D:$D,$X13)) -> INDIGO | B13: =IF($X13="","",INDEX('Raw Data'!$E:$E,$X13)) -> 6E232 | C13: =IF($X13="","",IF($Y13="","Not linked",IF(INDEX('Flight Rates'!$G:$G,$Y13)<>"",INDEX('Flight Rates'!$G:$G,$Y13),IF($Z13="NO TARIFF LOADED","No tariff","No rate")))) -> GCR | D13: =IF($X13="","",INDEX('Raw Data'!$F:$F,$X13)) -> 18:30 | E13: =IF($Y13="","",IF(INDEX('Flight Rates'!$K:$K,$Y13)="","",INDEX('Flight Rates'!$K:$K,$Y13)+N($T13)+N($U13))) -> 92 | F13: =IF($Y13="","",IF(INDEX('Flight Rates'!$L:$L,$Y13)="","",INDEX('Flight Rates'!$L:$L,$Y13)+N($T13)+N($U13))) -> 90 | T13: =IF($Y13="","",N(INDEX('Flight Rates'!$S:$S,$Y13))) -> 4 | U13: =IF(OR($Y13="",$C13="No tariff",$C13="No rate"),"",IFERROR(N(INDEX('Add-on Rates'!$C:$C,MATCH($A13,'Add-on Rates'!$A:$A,0))),0)) -> 18 | X13: =IFERROR(SMALL('Raw Data'!$O$2:$O$1680,2),"") -> 326 | Y13: =IF($X13="","",IFERROR(MATCH($B$3&"|"&$G$3&"|"&$B13&"|"&$D13,'Flight Rates'!$A:$A,0),"")) -> 301 | Z13: =IF($Y13="","",INDEX('Flight Rates'!$P:$P,$Y13)) -> OK
A14: =IF($X14="","",INDEX('Raw Data'!$D:$D,$X14)) -> AIRINDIA | B14: =IF($X14="","",INDEX('Raw Data'!$E:$E,$X14)) -> AI1721 | C14: =IF($X14="","",IF($Y14="","Not linked",IF(INDEX('Flight Rates'!$G:$G,$Y14)<>"",INDEX('Flight Rates'!$G:$G,$Y14),IF($Z14="NO TARIFF LOADED","No tariff","No rate")))) -> PRIME | D14: =IF($X14="","",INDEX('Raw Data'!$F:$F,$X14)) -> 11:30 | E14: =IF($Y14="","",IF(INDEX('Flight Rates'!$K:$K,$Y14)="","",INDEX('Flight Rates'!$K:$K,$Y14)+N($T14)+N($U14))) -> 102 | F14: =IF($Y14="","",IF(INDEX('Flight Rates'!$L:$L,$Y14)="","",INDEX('Flight Rates'!$L:$L,$Y14)+N($T14)+N($U14))) -> 92 | T14: =IF($Y14="","",N(INDEX('Flight Rates'!$S:$S,$Y14))) -> 15 | U14: =IF(OR($Y14="",$C14="No tariff",$C14="No rate"),"",IFERROR(N(INDEX('Add-on Rates'!$C:$C,MATCH($A14,'Add-on Rates'!$A:$A,0))),0)) -> 12 | X14: =IFERROR(SMALL('Raw Data'!$O$2:$O$1680,3),"") -> 327 | Y14: =IF($X14="","",IFERROR(MATCH($B$3&"|"&$G$3&"|"&$B14&"|"&$D14,'Flight Rates'!$A:$A,0),"")) -> 302 | Z14: =IF($Y14="","",INDEX('Flight Rates'!$P:$P,$Y14)) -> OK
A15: =IF($X15="","",INDEX('Raw Data'!$D:$D,$X15)) -> AIRINDIA | B15: =IF($X15="","",INDEX('Raw Data'!$E:$E,$X15)) -> AI1753 | C15: =IF($X15="","",IF($Y15="","Not linked",IF(INDEX('Flight Rates'!$G:$G,$Y15)<>"",INDEX('Flight Rates'!$G:$G,$Y15),IF($Z15="NO TARIFF LOADED","No tariff","No rate")))) -> PRIME | D15: =IF($X15="","",INDEX('Raw Data'!$F:$F,$X15)) -> 15:00 | E15: =IF($Y15="","",IF(INDEX('Flight Rates'!$K:$K,$Y15)="","",INDEX('Flight Rates'!$K:$K,$Y15)+N($T15)+N($U15))) -> 102 | F15: =IF($Y15="","",IF(INDEX('Flight Rates'!$L:$L,$Y15)="","",INDEX('Flight Rates'!$L:$L,$Y15)+N($T15)+N($U15))) -> 92 | T15: =IF($Y15="","",N(INDEX('Flight Rates'!$S:$S,$Y15))) -> 15 | U15: =IF(OR($Y15="",$C15="No tariff",$C15="No rate"),"",IFERROR(N(INDEX('Add-on Rates'!$C:$C,MATCH($A15,'Add-on Rates'!$A:$A,0))),0)) -> 12 | X15: =IFERROR(SMALL('Raw Data'!$O$2:$O$1680,4),"") -> 328 | Y15: =IF($X15="","",IFERROR(MATCH($B$3&"|"&$G$3&"|"&$B15&"|"&$D15,'Flight Rates'!$A:$A,0),"")) -> 303 | Z15: =IF($Y15="","",INDEX('Flight Rates'!$P:$P,$Y15)) -> OK
A16: =IF($X16="","",INDEX('Raw Data'!$D:$D,$X16)) | B16: =IF($X16="","",INDEX('Raw Data'!$E:$E,$X16)) | C16: =IF($X16="","",IF($Y16="","Not linked",IF(INDEX('Flight Rates'!$G:$G,$Y16)<>"",INDEX('Flight Rates'!$G:$G,$Y16),IF($Z16="NO TARIFF LOADED","No tariff","No rate")))) | D16: =IF($X16="","",INDEX('Raw Data'!$F:$F,$X16)) | E16: =IF($Y16="","",IF(INDEX('Flight Rates'!$K:$K,$Y16)="","",INDEX('Flight Rates'!$K:$K,$Y16)+N($T16)+N($U16))) | F16: =IF($Y16="","",IF(INDEX('Flight Rates'!$L:$L,$Y16)="","",INDEX('Flight Rates'!$L:$L,$Y16)+N($T16)+N($U16))) | T16: =IF($Y16="","",N(INDEX('Flight Rates'!$S:$S,$Y16))) | U16: =IF(OR($Y16="",$C16="No tariff",$C16="No rate"),"",IFERROR(N(INDEX('Add-on Rates'!$C:$C,MATCH($A16,'Add-on Rates'!$A:$A,0))),0)) | X16: =IFERROR(SMALL('Raw Data'!$O$2:$O$1680,5),"") | Y16: =IF($X16="","",IFERROR(MATCH($B$3&"|"&$G$3&"|"&$B16&"|"&$D16,'Flight Rates'!$A:$A,0),"")) | Z16: =IF($Y16="","",INDEX('Flight Rates'!$P:$P,$Y16))
A17: =IF($X17="","",INDEX('Raw Data'!$D:$D,$X17)) | B17: =IF($X17="","",INDEX('Raw Data'!$E:$E,$X17)) | C17: =IF($X17="","",IF($Y17="","Not linked",IF(INDEX('Flight Rates'!$G:$G,$Y17)<>"",INDEX('Flight Rates'!$G:$G,$Y17),IF($Z17="NO TARIFF LOADED","No tariff","No rate")))) | D17: =IF($X17="","",INDEX('Raw Data'!$F:$F,$X17)) | E17: =IF($Y17="","",IF(INDEX('Flight Rates'!$K:$K,$Y17)="","",INDEX('Flight Rates'!$K:$K,$Y17)+N($T17)+N($U17))) | F17: =IF($Y17="","",IF(INDEX('Flight Rates'!$L:$L,$Y17)="","",INDEX('Flight Rates'!$L:$L,$Y17)+N($T17)+N($U17))) | T17: =IF($Y17="","",N(INDEX('Flight Rates'!$S:$S,$Y17))) | U17: =IF(OR($Y17="",$C17="No tariff",$C17="No rate"),"",IFERROR(N(INDEX('Add-on Rates'!$C:$C,MATCH($A17,'Add-on Rates'!$A:$A,0))),0)) | X17: =IFERROR(SMALL('Raw Data'!$O$2:$O$1680,6),"") | Y17: =IF($X17="","",IFERROR(MATCH($B$3&"|"&$G$3&"|"&$B17&"|"&$D17,'Flight Rates'!$A:$A,0),"")) | Z17: =IF($Y17="","",INDEX('Flight Rates'!$P:$P,$Y17))
A18: =IF($X18="","",INDEX('Raw Data'!$D:$D,$X18)) | B18: =IF($X18="","",INDEX('Raw Data'!$E:$E,$X18)) | C18: =IF($X18="","",IF($Y18="","Not linked",IF(INDEX('Flight Rates'!$G:$G,$Y18)<>"",INDEX('Flight Rates'!$G:$G,$Y18),IF($Z18="NO TARIFF LOADED","No tariff","No rate")))) | D18: =IF($X18="","",INDEX('Raw Data'!$F:$F,$X18)) | E18: =IF($Y18="","",IF(INDEX('Flight Rates'!$K:$K,$Y18)="","",INDEX('Flight Rates'!$K:$K,$Y18)+N($T18)+N($U18))) | F18: =IF($Y18="","",IF(INDEX('Flight Rates'!$L:$L,$Y18)="","",INDEX('Flight Rates'!$L:$L,$Y18)+N($T18)+N($U18))) | T18: =IF($Y18="","",N(INDEX('Flight Rates'!$S:$S,$Y18))) | U18: =IF(OR($Y18="",$C18="No tariff",$C18="No rate"),"",IFERROR(N(INDEX('Add-on Rates'!$C:$C,MATCH($A18,'Add-on Rates'!$A:$A,0))),0)) | X18: =IFERROR(SMALL('Raw Data'!$O$2:$O$1680,7),"") | Y18: =IF($X18="","",IFERROR(MATCH($B$3&"|"&$G$3&"|"&$B18&"|"&$D18,'Flight Rates'!$A:$A,0),"")) | Z18: =IF($Y18="","",INDEX('Flight Rates'!$P:$P,$Y18))
A19: =IF($X19="","",INDEX('Raw Data'!$D:$D,$X19)) | B19: =IF($X19="","",INDEX('Raw Data'!$E:$E,$X19)) | C19: =IF($X19="","",IF($Y19="","Not linked",IF(INDEX('Flight Rates'!$G:$G,$Y19)<>"",INDEX('Flight Rates'!$G:$G,$Y19),IF($Z19="NO TARIFF LOADED","No tariff","No rate")))) | D19: =IF($X19="","",INDEX('Raw Data'!$F:$F,$X19)) | E19: =IF($Y19="","",IF(INDEX('Flight Rates'!$K:$K,$Y19)="","",INDEX('Flight Rates'!$K:$K,$Y19)+N($T19)+N($U19))) | F19: =IF($Y19="","",IF(INDEX('Flight Rates'!$L:$L,$Y19)="","",INDEX('Flight Rates'!$L:$L,$Y19)+N($T19)+N($U19))) | T19: =IF($Y19="","",N(INDEX('Flight Rates'!$S:$S,$Y19))) | U19: =IF(OR($Y19="",$C19="No tariff",$C19="No rate"),"",IFERROR(N(INDEX('Add-on Rates'!$C:$C,MATCH($A19,'Add-on Rates'!$A:$A,0))),0)) | X19: =IFERROR(SMALL('Raw Data'!$O$2:$O$1680,8),"") | Y19: =IF($X19="","",IFERROR(MATCH($B$3&"|"&$G$3&"|"&$B19&"|"&$D19,'Flight Rates'!$A:$A,0),"")) | Z19: =IF($Y19="","",INDEX('Flight Rates'!$P:$P,$Y19))
A20: =IF($X20="","",INDEX('Raw Data'!$D:$D,$X20)) | B20: =IF($X20="","",INDEX('Raw Data'!$E:$E,$X20)) | C20: =IF($X20="","",IF($Y20="","Not linked",IF(INDEX('Flight Rates'!$G:$G,$Y20)<>"",INDEX('Flight Rates'!$G:$G,$Y20),IF($Z20="NO TARIFF LOADED","No tariff","No rate")))) | D20: =IF($X20="","",INDEX('Raw Data'!$F:$F,$X20)) | E20: =IF($Y20="","",IF(INDEX('Flight Rates'!$K:$K,$Y20)="","",INDEX('Flight Rates'!$K:$K,$Y20)+N($T20)+N($U20))) | F20: =IF($Y20="","",IF(INDEX('Flight Rates'!$L:$L,$Y20)="","",INDEX('Flight Rates'!$L:$L,$Y20)+N($T20)+N($U20))) | T20: =IF($Y20="","",N(INDEX('Flight Rates'!$S:$S,$Y20))) | U20: =IF(OR($Y20="",$C20="No tariff",$C20="No rate"),"",IFERROR(N(INDEX('Add-on Rates'!$C:$C,MATCH($A20,'Add-on Rates'!$A:$A,0))),0)) | X20: =IFERROR(SMALL('Raw Data'!$O$2:$O$1680,9),"") | Y20: =IF($X20="","",IFERROR(MATCH($B$3&"|"&$G$3&"|"&$B20&"|"&$D20,'Flight Rates'!$A:$A,0),"")) | Z20: =IF($Y20="","",INDEX('Flight Rates'!$P:$P,$Y20))
A21: =IF($X21="","",INDEX('Raw Data'!$D:$D,$X21)) | B21: =IF($X21="","",INDEX('Raw Data'!$E:$E,$X21)) | C21: =IF($X21="","",IF($Y21="","Not linked",IF(INDEX('Flight Rates'!$G:$G,$Y21)<>"",INDEX('Flight Rates'!$G:$G,$Y21),IF($Z21="NO TARIFF LOADED","No tariff","No rate")))) | D21: =IF($X21="","",INDEX('Raw Data'!$F:$F,$X21)) | E21: =IF($Y21="","",IF(INDEX('Flight Rates'!$K:$K,$Y21)="","",INDEX('Flight Rates'!$K:$K,$Y21)+N($T21)+N($U21))) | F21: =IF($Y21="","",IF(INDEX('Flight Rates'!$L:$L,$Y21)="","",INDEX('Flight Rates'!$L:$L,$Y21)+N($T21)+N($U21))) | T21: =IF($Y21="","",N(INDEX('Flight Rates'!$S:$S,$Y21))) | U21: =IF(OR($Y21="",$C21="No tariff",$C21="No rate"),"",IFERROR(N(INDEX('Add-on Rates'!$C:$C,MATCH($A21,'Add-on Rates'!$A:$A,0))),0)) | X21: =IFERROR(SMALL('Raw Data'!$O$2:$O$1680,10),"") | Y21: =IF($X21="","",IFERROR(MATCH($B$3&"|"&$G$3&"|"&$B21&"|"&$D21,'Flight Rates'!$A:$A,0),"")) | Z21: =IF($Y21="","",INDEX('Flight Rates'!$P:$P,$Y21))
A22: =IF($X22="","",INDEX('Raw Data'!$D:$D,$X22)) | B22: =IF($X22="","",INDEX('Raw Data'!$E:$E,$X22)) | C22: =IF($X22="","",IF($Y22="","Not linked",IF(INDEX('Flight Rates'!$G:$G,$Y22)<>"",INDEX('Flight Rates'!$G:$G,$Y22),IF($Z22="NO TARIFF LOADED","No tariff","No rate")))) | D22: =IF($X22="","",INDEX('Raw Data'!$F:$F,$X22)) | E22: =IF($Y22="","",IF(INDEX('Flight Rates'!$K:$K,$Y22)="","",INDEX('Flight Rates'!$K:$K,$Y22)+N($T22)+N($U22))) | F22: =IF($Y22="","",IF(INDEX('Flight Rates'!$L:$L,$Y22)="","",INDEX('Flight Rates'!$L:$L,$Y22)+N($T22)+N($U22))) | T22: =IF($Y22="","",N(INDEX('Flight Rates'!$S:$S,$Y22))) | U22: =IF(OR($Y22="",$C22="No tariff",$C22="No rate"),"",IFERROR(N(INDEX('Add-on Rates'!$C:$C,MATCH($A22,'Add-on Rates'!$A:$A,0))),0)) | X22: =IFERROR(SMALL('Raw Data'!$O$2:$O$1680,11),"") | Y22: =IF($X22="","",IFERROR(MATCH($B$3&"|"&$G$3&"|"&$B22&"|"&$D22,'Flight Rates'!$A:$A,0),"")) | Z22: =IF($Y22="","",INDEX('Flight Rates'!$P:$P,$Y22))
A23: =IF($X23="","",INDEX('Raw Data'!$D:$D,$X23)) | B23: =IF($X23="","",INDEX('Raw Data'!$E:$E,$X23)) | C23: =IF($X23="","",IF($Y23="","Not linked",IF(INDEX('Flight Rates'!$G:$G,$Y23)<>"",INDEX('Flight Rates'!$G:$G,$Y23),IF($Z23="NO TARIFF LOADED","No tariff","No rate")))) | D23: =IF($X23="","",INDEX('Raw Data'!$F:$F,$X23)) | E23: =IF($Y23="","",IF(INDEX('Flight Rates'!$K:$K,$Y23)="","",INDEX('Flight Rates'!$K:$K,$Y23)+N($T23)+N($U23))) | F23: =IF($Y23="","",IF(INDEX('Flight Rates'!$L:$L,$Y23)="","",INDEX('Flight Rates'!$L:$L,$Y23)+N($T23)+N($U23))) | T23: =IF($Y23="","",N(INDEX('Flight Rates'!$S:$S,$Y23))) | U23: =IF(OR($Y23="",$C23="No tariff",$C23="No rate"),"",IFERROR(N(INDEX('Add-on Rates'!$C:$C,MATCH($A23,'Add-on Rates'!$A:$A,0))),0)) | X23: =IFERROR(SMALL('Raw Data'!$O$2:$O$1680,12),"") | Y23: =IF($X23="","",IFERROR(MATCH($B$3&"|"&$G$3&"|"&$B23&"|"&$D23,'Flight Rates'!$A:$A,0),"")) | Z23: =IF($Y23="","",INDEX('Flight Rates'!$P:$P,$Y23))
A24: =IF($X24="","",INDEX('Raw Data'!$D:$D,$X24)) | B24: =IF($X24="","",INDEX('Raw Data'!$E:$E,$X24)) | C24: =IF($X24="","",IF($Y24="","Not linked",IF(INDEX('Flight Rates'!$G:$G,$Y24)<>"",INDEX('Flight Rates'!$G:$G,$Y24),IF($Z24="NO TARIFF LOADED","No tariff","No rate")))) | D24: =IF($X24="","",INDEX('Raw Data'!$F:$F,$X24)) | E24: =IF($Y24="","",IF(INDEX('Flight Rates'!$K:$K,$Y24)="","",INDEX('Flight Rates'!$K:$K,$Y24)+N($T24)+N($U24))) | F24: =IF($Y24="","",IF(INDEX('Flight Rates'!$L:$L,$Y24)="","",INDEX('Flight Rates'!$L:$L,$Y24)+N($T24)+N($U24))) | T24: =IF($Y24="","",N(INDEX('Flight Rates'!$S:$S,$Y24))) | U24: =IF(OR($Y24="",$C24="No tariff",$C24="No rate"),"",IFERROR(N(INDEX('Add-on Rates'!$C:$C,MATCH($A24,'Add-on Rates'!$A:$A,0))),0)) | X24: =IFERROR(SMALL('Raw Data'!$O$2:$O$1680,13),"") | Y24: =IF($X24="","",IFERROR(MATCH($B$3&"|"&$G$3&"|"&$B24&"|"&$D24,'Flight Rates'!$A:$A,0),"")) | Z24: =IF($Y24="","",INDEX('Flight Rates'!$P:$P,$Y24))
A25: =IF($X25="","",INDEX('Raw Data'!$D:$D,$X25)) | B25: =IF($X25="","",INDEX('Raw Data'!$E:$E,$X25)) | C25: =IF($X25="","",IF($Y25="","Not linked",IF(INDEX('Flight Rates'!$G:$G,$Y25)<>"",INDEX('Flight Rates'!$G:$G,$Y25),IF($Z25="NO TARIFF LOADED","No tariff","No rate")))) | D25: =IF($X25="","",INDEX('Raw Data'!$F:$F,$X25)) | E25: =IF($Y25="","",IF(INDEX('Flight Rates'!$K:$K,$Y25)="","",INDEX('Flight Rates'!$K:$K,$Y25)+N($T25)+N($U25))) | F25: =IF($Y25="","",IF(INDEX('Flight Rates'!$L:$L,$Y25)="","",INDEX('Flight Rates'!$L:$L,$Y25)+N($T25)+N($U25))) | T25: =IF($Y25="","",N(INDEX('Flight Rates'!$S:$S,$Y25))) | U25: =IF(OR($Y25="",$C25="No tariff",$C25="No rate"),"",IFERROR(N(INDEX('Add-on Rates'!$C:$C,MATCH($A25,'Add-on Rates'!$A:$A,0))),0)) | X25: =IFERROR(SMALL('Raw Data'!$O$2:$O$1680,14),"") | Y25: =IF($X25="","",IFERROR(MATCH($B$3&"|"&$G$3&"|"&$B25&"|"&$D25,'Flight Rates'!$A:$A,0),"")) | Z25: =IF($Y25="","",INDEX('Flight Rates'!$P:$P,$Y25))
A26: =IF($X26="","",INDEX('Raw Data'!$D:$D,$X26)) | B26: =IF($X26="","",INDEX('Raw Data'!$E:$E,$X26)) | C26: =IF($X26="","",IF($Y26="","Not linked",IF(INDEX('Flight Rates'!$G:$G,$Y26)<>"",INDEX('Flight Rates'!$G:$G,$Y26),IF($Z26="NO TARIFF LOADED","No tariff","No rate")))) | D26: =IF($X26="","",INDEX('Raw Data'!$F:$F,$X26)) | E26: =IF($Y26="","",IF(INDEX('Flight Rates'!$K:$K,$Y26)="","",INDEX('Flight Rates'!$K:$K,$Y26)+N($T26)+N($U26))) | F26: =IF($Y26="","",IF(INDEX('Flight Rates'!$L:$L,$Y26)="","",INDEX('Flight Rates'!$L:$L,$Y26)+N($T26)+N($U26))) | T26: =IF($Y26="","",N(INDEX('Flight Rates'!$S:$S,$Y26))) | U26: =IF(OR($Y26="",$C26="No tariff",$C26="No rate"),"",IFERROR(N(INDEX('Add-on Rates'!$C:$C,MATCH($A26,'Add-on Rates'!$A:$A,0))),0)) | X26: =IFERROR(SMALL('Raw Data'!$O$2:$O$1680,15),"") | Y26: =IF($X26="","",IFERROR(MATCH($B$3&"|"&$G$3&"|"&$B26&"|"&$D26,'Flight Rates'!$A:$A,0),"")) | Z26: =IF($Y26="","",INDEX('Flight Rates'!$P:$P,$Y26))
A27: =IF($X27="","",INDEX('Raw Data'!$D:$D,$X27)) | B27: =IF($X27="","",INDEX('Raw Data'!$E:$E,$X27)) | C27: =IF($X27="","",IF($Y27="","Not linked",IF(INDEX('Flight Rates'!$G:$G,$Y27)<>"",INDEX('Flight Rates'!$G:$G,$Y27),IF($Z27="NO TARIFF LOADED","No tariff","No rate")))) | D27: =IF($X27="","",INDEX('Raw Data'!$F:$F,$X27)) | E27: =IF($Y27="","",IF(INDEX('Flight Rates'!$K:$K,$Y27)="","",INDEX('Flight Rates'!$K:$K,$Y27)+N($T27)+N($U27))) | F27: =IF($Y27="","",IF(INDEX('Flight Rates'!$L:$L,$Y27)="","",INDEX('Flight Rates'!$L:$L,$Y27)+N($T27)+N($U27))) | T27: =IF($Y27="","",N(INDEX('Flight Rates'!$S:$S,$Y27))) | U27: =IF(OR($Y27="",$C27="No tariff",$C27="No rate"),"",IFERROR(N(INDEX('Add-on Rates'!$C:$C,MATCH($A27,'Add-on Rates'!$A:$A,0))),0)) | X27: =IFERROR(SMALL('Raw Data'!$O$2:$O$1680,16),"") | Y27: =IF($X27="","",IFERROR(MATCH($B$3&"|"&$G$3&"|"&$B27&"|"&$D27,'Flight Rates'!$A:$A,0),"")) | Z27: =IF($Y27="","",INDEX('Flight Rates'!$P:$P,$Y27))
A28: =IF($X28="","",INDEX('Raw Data'!$D:$D,$X28)) | B28: =IF($X28="","",INDEX('Raw Data'!$E:$E,$X28)) | C28: =IF($X28="","",IF($Y28="","Not linked",IF(INDEX('Flight Rates'!$G:$G,$Y28)<>"",INDEX('Flight Rates'!$G:$G,$Y28),IF($Z28="NO TARIFF LOADED","No tariff","No rate")))) | D28: =IF($X28="","",INDEX('Raw Data'!$F:$F,$X28)) | E28: =IF($Y28="","",IF(INDEX('Flight Rates'!$K:$K,$Y28)="","",INDEX('Flight Rates'!$K:$K,$Y28)+N($T28)+N($U28))) | F28: =IF($Y28="","",IF(INDEX('Flight Rates'!$L:$L,$Y28)="","",INDEX('Flight Rates'!$L:$L,$Y28)+N($T28)+N($U28))) | T28: =IF($Y28="","",N(INDEX('Flight Rates'!$S:$S,$Y28))) | U28: =IF(OR($Y28="",$C28="No tariff",$C28="No rate"),"",IFERROR(N(INDEX('Add-on Rates'!$C:$C,MATCH($A28,'Add-on Rates'!$A:$A,0))),0)) | X28: =IFERROR(SMALL('Raw Data'!$O$2:$O$1680,17),"") | Y28: =IF($X28="","",IFERROR(MATCH($B$3&"|"&$G$3&"|"&$B28&"|"&$D28,'Flight Rates'!$A:$A,0),"")) | Z28: =IF($Y28="","",INDEX('Flight Rates'!$P:$P,$Y28))
A29: =IF($X29="","",INDEX('Raw Data'!$D:$D,$X29)) | B29: =IF($X29="","",INDEX('Raw Data'!$E:$E,$X29)) | C29: =IF($X29="","",IF($Y29="","Not linked",IF(INDEX('Flight Rates'!$G:$G,$Y29)<>"",INDEX('Flight Rates'!$G:$G,$Y29),IF($Z29="NO TARIFF LOADED","No tariff","No rate")))) | D29: =IF($X29="","",INDEX('Raw Data'!$F:$F,$X29)) | E29: =IF($Y29="","",IF(INDEX('Flight Rates'!$K:$K,$Y29)="","",INDEX('Flight Rates'!$K:$K,$Y29)+N($T29)+N($U29))) | F29: =IF($Y29="","",IF(INDEX('Flight Rates'!$L:$L,$Y29)="","",INDEX('Flight Rates'!$L:$L,$Y29)+N($T29)+N($U29))) | T29: =IF($Y29="","",N(INDEX('Flight Rates'!$S:$S,$Y29))) | U29: =IF(OR($Y29="",$C29="No tariff",$C29="No rate"),"",IFERROR(N(INDEX('Add-on Rates'!$C:$C,MATCH($A29,'Add-on Rates'!$A:$A,0))),0)) | X29: =IFERROR(SMALL('Raw Data'!$O$2:$O$1680,18),"") | Y29: =IF($X29="","",IFERROR(MATCH($B$3&"|"&$G$3&"|"&$B29&"|"&$D29,'Flight Rates'!$A:$A,0),"")) | Z29: =IF($Y29="","",INDEX('Flight Rates'!$P:$P,$Y29))
A30: =IF($X30="","",INDEX('Raw Data'!$D:$D,$X30)) | B30: =IF($X30="","",INDEX('Raw Data'!$E:$E,$X30)) | C30: =IF($X30="","",IF($Y30="","Not linked",IF(INDEX('Flight Rates'!$G:$G,$Y30)<>"",INDEX('Flight Rates'!$G:$G,$Y30),IF($Z30="NO TARIFF LOADED","No tariff","No rate")))) | D30: =IF($X30="","",INDEX('Raw Data'!$F:$F,$X30)) | E30: =IF($Y30="","",IF(INDEX('Flight Rates'!$K:$K,$Y30)="","",INDEX('Flight Rates'!$K:$K,$Y30)+N($T30)+N($U30))) | F30: =IF($Y30="","",IF(INDEX('Flight Rates'!$L:$L,$Y30)="","",INDEX('Flight Rates'!$L:$L,$Y30)+N($T30)+N($U30))) | T30: =IF($Y30="","",N(INDEX('Flight Rates'!$S:$S,$Y30))) | U30: =IF(OR($Y30="",$C30="No tariff",$C30="No rate"),"",IFERROR(N(INDEX('Add-on Rates'!$C:$C,MATCH($A30,'Add-on Rates'!$A:$A,0))),0)) | X30: =IFERROR(SMALL('Raw Data'!$O$2:$O$1680,19),"") | Y30: =IF($X30="","",IFERROR(MATCH($B$3&"|"&$G$3&"|"&$B30&"|"&$D30,'Flight Rates'!$A:$A,0),"")) | Z30: =IF($Y30="","",INDEX('Flight Rates'!$P:$P,$Y30))
A31: =IF($X31="","",INDEX('Raw Data'!$D:$D,$X31)) | B31: =IF($X31="","",INDEX('Raw Data'!$E:$E,$X31)) | C31: =IF($X31="","",IF($Y31="","Not linked",IF(INDEX('Flight Rates'!$G:$G,$Y31)<>"",INDEX('Flight Rates'!$G:$G,$Y31),IF($Z31="NO TARIFF LOADED","No tariff","No rate")))) | D31: =IF($X31="","",INDEX('Raw Data'!$F:$F,$X31)) | E31: =IF($Y31="","",IF(INDEX('Flight Rates'!$K:$K,$Y31)="","",INDEX('Flight Rates'!$K:$K,$Y31)+N($T31)+N($U31))) | F31: =IF($Y31="","",IF(INDEX('Flight Rates'!$L:$L,$Y31)="","",INDEX('Flight Rates'!$L:$L,$Y31)+N($T31)+N($U31))) | T31: =IF($Y31="","",N(INDEX('Flight Rates'!$S:$S,$Y31))) | U31: =IF(OR($Y31="",$C31="No tariff",$C31="No rate"),"",IFERROR(N(INDEX('Add-on Rates'!$C:$C,MATCH($A31,'Add-on Rates'!$A:$A,0))),0)) | X31: =IFERROR(SMALL('Raw Data'!$O$2:$O$1680,20),"") | Y31: =IF($X31="","",IFERROR(MATCH($B$3&"|"&$G$3&"|"&$B31&"|"&$D31,'Flight Rates'!$A:$A,0),"")) | Z31: =IF($Y31="","",INDEX('Flight Rates'!$P:$P,$Y31))
A32: =IF($X32="","",INDEX('Raw Data'!$D:$D,$X32)) | B32: =IF($X32="","",INDEX('Raw Data'!$E:$E,$X32)) | C32: =IF($X32="","",IF($Y32="","Not linked",IF(INDEX('Flight Rates'!$G:$G,$Y32)<>"",INDEX('Flight Rates'!$G:$G,$Y32),IF($Z32="NO TARIFF LOADED","No tariff","No rate")))) | D32: =IF($X32="","",INDEX('Raw Data'!$F:$F,$X32)) | E32: =IF($Y32="","",IF(INDEX('Flight Rates'!$K:$K,$Y32)="","",INDEX('Flight Rates'!$K:$K,$Y32)+N($T32)+N($U32))) | F32: =IF($Y32="","",IF(INDEX('Flight Rates'!$L:$L,$Y32)="","",INDEX('Flight Rates'!$L:$L,$Y32)+N($T32)+N($U32))) | T32: =IF($Y32="","",N(INDEX('Flight Rates'!$S:$S,$Y32))) | U32: =IF(OR($Y32="",$C32="No tariff",$C32="No rate"),"",IFERROR(N(INDEX('Add-on Rates'!$C:$C,MATCH($A32,'Add-on Rates'!$A:$A,0))),0)) | X32: =IFERROR(SMALL('Raw Data'!$O$2:$O$1680,21),"") | Y32: =IF($X32="","",IFERROR(MATCH($B$3&"|"&$G$3&"|"&$B32&"|"&$D32,'Flight Rates'!$A:$A,0),"")) | Z32: =IF($Y32="","",INDEX('Flight Rates'!$P:$P,$Y32))
A33: =IF($X33="","",INDEX('Raw Data'!$D:$D,$X33)) | B33: =IF($X33="","",INDEX('Raw Data'!$E:$E,$X33)) | C33: =IF($X33="","",IF($Y33="","Not linked",IF(INDEX('Flight Rates'!$G:$G,$Y33)<>"",INDEX('Flight Rates'!$G:$G,$Y33),IF($Z33="NO TARIFF LOADED","No tariff","No rate")))) | D33: =IF($X33="","",INDEX('Raw Data'!$F:$F,$X33)) | E33: =IF($Y33="","",IF(INDEX('Flight Rates'!$K:$K,$Y33)="","",INDEX('Flight Rates'!$K:$K,$Y33)+N($T33)+N($U33))) | F33: =IF($Y33="","",IF(INDEX('Flight Rates'!$L:$L,$Y33)="","",INDEX('Flight Rates'!$L:$L,$Y33)+N($T33)+N($U33))) | T33: =IF($Y33="","",N(INDEX('Flight Rates'!$S:$S,$Y33))) | U33: =IF(OR($Y33="",$C33="No tariff",$C33="No rate"),"",IFERROR(N(INDEX('Add-on Rates'!$C:$C,MATCH($A33,'Add-on Rates'!$A:$A,0))),0)) | X33: =IFERROR(SMALL('Raw Data'!$O$2:$O$1680,22),"") | Y33: =IF($X33="","",IFERROR(MATCH($B$3&"|"&$G$3&"|"&$B33&"|"&$D33,'Flight Rates'!$A:$A,0),"")) | Z33: =IF($Y33="","",INDEX('Flight Rates'!$P:$P,$Y33))
A34: =IF($X34="","",INDEX('Raw Data'!$D:$D,$X34)) | B34: =IF($X34="","",INDEX('Raw Data'!$E:$E,$X34)) | C34: =IF($X34="","",IF($Y34="","Not linked",IF(INDEX('Flight Rates'!$G:$G,$Y34)<>"",INDEX('Flight Rates'!$G:$G,$Y34),IF($Z34="NO TARIFF LOADED","No tariff","No rate")))) | D34: =IF($X34="","",INDEX('Raw Data'!$F:$F,$X34)) | E34: =IF($Y34="","",IF(INDEX('Flight Rates'!$K:$K,$Y34)="","",INDEX('Flight Rates'!$K:$K,$Y34)+N($T34)+N($U34))) | F34: =IF($Y34="","",IF(INDEX('Flight Rates'!$L:$L,$Y34)="","",INDEX('Flight Rates'!$L:$L,$Y34)+N($T34)+N($U34))) | T34: =IF($Y34="","",N(INDEX('Flight Rates'!$S:$S,$Y34))) | U34: =IF(OR($Y34="",$C34="No tariff",$C34="No rate"),"",IFERROR(N(INDEX('Add-on Rates'!$C:$C,MATCH($A34,'Add-on Rates'!$A:$A,0))),0)) | X34: =IFERROR(SMALL('Raw Data'!$O$2:$O$1680,23),"") | Y34: =IF($X34="","",IFERROR(MATCH($B$3&"|"&$G$3&"|"&$B34&"|"&$D34,'Flight Rates'!$A:$A,0),"")) | Z34: =IF($Y34="","",INDEX('Flight Rates'!$P:$P,$Y34))
A35: =IF($X35="","",INDEX('Raw Data'!$D:$D,$X35)) | B35: =IF($X35="","",INDEX('Raw Data'!$E:$E,$X35)) | C35: =IF($X35="","",IF($Y35="","Not linked",IF(INDEX('Flight Rates'!$G:$G,$Y35)<>"",INDEX('Flight Rates'!$G:$G,$Y35),IF($Z35="NO TARIFF LOADED","No tariff","No rate")))) | D35: =IF($X35="","",INDEX('Raw Data'!$F:$F,$X35)) | E35: =IF($Y35="","",IF(INDEX('Flight Rates'!$K:$K,$Y35)="","",INDEX('Flight Rates'!$K:$K,$Y35)+N($T35)+N($U35))) | F35: =IF($Y35="","",IF(INDEX('Flight Rates'!$L:$L,$Y35)="","",INDEX('Flight Rates'!$L:$L,$Y35)+N($T35)+N($U35))) | T35: =IF($Y35="","",N(INDEX('Flight Rates'!$S:$S,$Y35))) | U35: =IF(OR($Y35="",$C35="No tariff",$C35="No rate"),"",IFERROR(N(INDEX('Add-on Rates'!$C:$C,MATCH($A35,'Add-on Rates'!$A:$A,0))),0)) | X35: =IFERROR(SMALL('Raw Data'!$O$2:$O$1680,24),"") | Y35: =IF($X35="","",IFERROR(MATCH($B$3&"|"&$G$3&"|"&$B35&"|"&$D35,'Flight Rates'!$A:$A,0),"")) | Z35: =IF($Y35="","",INDEX('Flight Rates'!$P:$P,$Y35))
A36: =IF($X36="","",INDEX('Raw Data'!$D:$D,$X36)) | B36: =IF($X36="","",INDEX('Raw Data'!$E:$E,$X36)) | C36: =IF($X36="","",IF($Y36="","Not linked",IF(INDEX('Flight Rates'!$G:$G,$Y36)<>"",INDEX('Flight Rates'!$G:$G,$Y36),IF($Z36="NO TARIFF LOADED","No tariff","No rate")))) | D36: =IF($X36="","",INDEX('Raw Data'!$F:$F,$X36)) | E36: =IF($Y36="","",IF(INDEX('Flight Rates'!$K:$K,$Y36)="","",INDEX('Flight Rates'!$K:$K,$Y36)+N($T36)+N($U36))) | F36: =IF($Y36="","",IF(INDEX('Flight Rates'!$L:$L,$Y36)="","",INDEX('Flight Rates'!$L:$L,$Y36)+N($T36)+N($U36))) | T36: =IF($Y36="","",N(INDEX('Flight Rates'!$S:$S,$Y36))) | U36: =IF(OR($Y36="",$C36="No tariff",$C36="No rate"),"",IFERROR(N(INDEX('Add-on Rates'!$C:$C,MATCH($A36,'Add-on Rates'!$A:$A,0))),0)) | X36: =IFERROR(SMALL('Raw Data'!$O$2:$O$1680,25),"") | Y36: =IF($X36="","",IFERROR(MATCH($B$3&"|"&$G$3&"|"&$B36&"|"&$D36,'Flight Rates'!$A:$A,0),"")) | Z36: =IF($Y36="","",INDEX('Flight Rates'!$P:$P,$Y36))
A37: =IF($X37="","",INDEX('Raw Data'!$D:$D,$X37)) | B37: =IF($X37="","",INDEX('Raw Data'!$E:$E,$X37)) | C37: =IF($X37="","",IF($Y37="","Not linked",IF(INDEX('Flight Rates'!$G:$G,$Y37)<>"",INDEX('Flight Rates'!$G:$G,$Y37),IF($Z37="NO TARIFF LOADED","No tariff","No rate")))) | D37: =IF($X37="","",INDEX('Raw Data'!$F:$F,$X37)) | E37: =IF($Y37="","",IF(INDEX('Flight Rates'!$K:$K,$Y37)="","",INDEX('Flight Rates'!$K:$K,$Y37)+N($T37)+N($U37))) | F37: =IF($Y37="","",IF(INDEX('Flight Rates'!$L:$L,$Y37)="","",INDEX('Flight Rates'!$L:$L,$Y37)+N($T37)+N($U37))) | T37: =IF($Y37="","",N(INDEX('Flight Rates'!$S:$S,$Y37))) | U37: =IF(OR($Y37="",$C37="No tariff",$C37="No rate"),"",IFERROR(N(INDEX('Add-on Rates'!$C:$C,MATCH($A37,'Add-on Rates'!$A:$A,0))),0)) | X37: =IFERROR(SMALL('Raw Data'!$O$2:$O$1680,26),"") | Y37: =IF($X37="","",IFERROR(MATCH($B$3&"|"&$G$3&"|"&$B37&"|"&$D37,'Flight Rates'!$A:$A,0),"")) | Z37: =IF($Y37="","",INDEX('Flight Rates'!$P:$P,$Y37))
A38: =IF($X38="","",INDEX('Raw Data'!$D:$D,$X38)) | B38: =IF($X38="","",INDEX('Raw Data'!$E:$E,$X38)) | C38: =IF($X38="","",IF($Y38="","Not linked",IF(INDEX('Flight Rates'!$G:$G,$Y38)<>"",INDEX('Flight Rates'!$G:$G,$Y38),IF($Z38="NO TARIFF LOADED","No tariff","No rate")))) | D38: =IF($X38="","",INDEX('Raw Data'!$F:$F,$X38)) | E38: =IF($Y38="","",IF(INDEX('Flight Rates'!$K:$K,$Y38)="","",INDEX('Flight Rates'!$K:$K,$Y38)+N($T38)+N($U38))) | F38: =IF($Y38="","",IF(INDEX('Flight Rates'!$L:$L,$Y38)="","",INDEX('Flight Rates'!$L:$L,$Y38)+N($T38)+N($U38))) | T38: =IF($Y38="","",N(INDEX('Flight Rates'!$S:$S,$Y38))) | U38: =IF(OR($Y38="",$C38="No tariff",$C38="No rate"),"",IFERROR(N(INDEX('Add-on Rates'!$C:$C,MATCH($A38,'Add-on Rates'!$A:$A,0))),0)) | X38: =IFERROR(SMALL('Raw Data'!$O$2:$O$1680,27),"") | Y38: =IF($X38="","",IFERROR(MATCH($B$3&"|"&$G$3&"|"&$B38&"|"&$D38,'Flight Rates'!$A:$A,0),"")) | Z38: =IF($Y38="","",INDEX('Flight Rates'!$P:$P,$Y38))
A39: =IF($X39="","",INDEX('Raw Data'!$D:$D,$X39)) | B39: =IF($X39="","",INDEX('Raw Data'!$E:$E,$X39)) | C39: =IF($X39="","",IF($Y39="","Not linked",IF(INDEX('Flight Rates'!$G:$G,$Y39)<>"",INDEX('Flight Rates'!$G:$G,$Y39),IF($Z39="NO TARIFF LOADED","No tariff","No rate")))) | D39: =IF($X39="","",INDEX('Raw Data'!$F:$F,$X39)) | E39: =IF($Y39="","",IF(INDEX('Flight Rates'!$K:$K,$Y39)="","",INDEX('Flight Rates'!$K:$K,$Y39)+N($T39)+N($U39))) | F39: =IF($Y39="","",IF(INDEX('Flight Rates'!$L:$L,$Y39)="","",INDEX('Flight Rates'!$L:$L,$Y39)+N($T39)+N($U39))) | T39: =IF($Y39="","",N(INDEX('Flight Rates'!$S:$S,$Y39))) | U39: =IF(OR($Y39="",$C39="No tariff",$C39="No rate"),"",IFERROR(N(INDEX('Add-on Rates'!$C:$C,MATCH($A39,'Add-on Rates'!$A:$A,0))),0)) | X39: =IFERROR(SMALL('Raw Data'!$O$2:$O$1680,28),"") | Y39: =IF($X39="","",IFERROR(MATCH($B$3&"|"&$G$3&"|"&$B39&"|"&$D39,'Flight Rates'!$A:$A,0),"")) | Z39: =IF($Y39="","",INDEX('Flight Rates'!$P:$P,$Y39))
A40: =IF($X40="","",INDEX('Raw Data'!$D:$D,$X40)) | B40: =IF($X40="","",INDEX('Raw Data'!$E:$E,$X40)) | C40: =IF($X40="","",IF($Y40="","Not linked",IF(INDEX('Flight Rates'!$G:$G,$Y40)<>"",INDEX('Flight Rates'!$G:$G,$Y40),IF($Z40="NO TARIFF LOADED","No tariff","No rate")))) | D40: =IF($X40="","",INDEX('Raw Data'!$F:$F,$X40)) | E40: =IF($Y40="","",IF(INDEX('Flight Rates'!$K:$K,$Y40)="","",INDEX('Flight Rates'!$K:$K,$Y40)+N($T40)+N($U40))) | F40: =IF($Y40="","",IF(INDEX('Flight Rates'!$L:$L,$Y40)="","",INDEX('Flight Rates'!$L:$L,$Y40)+N($T40)+N($U40))) | T40: =IF($Y40="","",N(INDEX('Flight Rates'!$S:$S,$Y40))) | U40: =IF(OR($Y40="",$C40="No tariff",$C40="No rate"),"",IFERROR(N(INDEX('Add-on Rates'!$C:$C,MATCH($A40,'Add-on Rates'!$A:$A,0))),0)) | X40: =IFERROR(SMALL('Raw Data'!$O$2:$O$1680,29),"") | Y40: =IF($X40="","",IFERROR(MATCH($B$3&"|"&$G$3&"|"&$B40&"|"&$D40,'Flight Rates'!$A:$A,0),"")) | Z40: =IF($Y40="","",INDEX('Flight Rates'!$P:$P,$Y40))
A41: =IF($X41="","",INDEX('Raw Data'!$D:$D,$X41)) | B41: =IF($X41="","",INDEX('Raw Data'!$E:$E,$X41)) | C41: =IF($X41="","",IF($Y41="","Not linked",IF(INDEX('Flight Rates'!$G:$G,$Y41)<>"",INDEX('Flight Rates'!$G:$G,$Y41),IF($Z41="NO TARIFF LOADED","No tariff","No rate")))) | D41: =IF($X41="","",INDEX('Raw Data'!$F:$F,$X41)) | E41: =IF($Y41="","",IF(INDEX('Flight Rates'!$K:$K,$Y41)="","",INDEX('Flight Rates'!$K:$K,$Y41)+N($T41)+N($U41))) | F41: =IF($Y41="","",IF(INDEX('Flight Rates'!$L:$L,$Y41)="","",INDEX('Flight Rates'!$L:$L,$Y41)+N($T41)+N($U41))) | T41: =IF($Y41="","",N(INDEX('Flight Rates'!$S:$S,$Y41))) | U41: =IF(OR($Y41="",$C41="No tariff",$C41="No rate"),"",IFERROR(N(INDEX('Add-on Rates'!$C:$C,MATCH($A41,'Add-on Rates'!$A:$A,0))),0)) | X41: =IFERROR(SMALL('Raw Data'!$O$2:$O$1680,30),"") | Y41: =IF($X41="","",IFERROR(MATCH($B$3&"|"&$G$3&"|"&$B41&"|"&$D41,'Flight Rates'!$A:$A,0),"")) | Z41: =IF($Y41="","",INDEX('Flight Rates'!$P:$P,$Y41))
A42: =IF($X42="","",INDEX('Raw Data'!$D:$D,$X42)) | B42: =IF($X42="","",INDEX('Raw Data'!$E:$E,$X42)) | C42: =IF($X42="","",IF($Y42="","Not linked",IF(INDEX('Flight Rates'!$G:$G,$Y42)<>"",INDEX('Flight Rates'!$G:$G,$Y42),IF($Z42="NO TARIFF LOADED","No tariff","No rate")))) | D42: =IF($X42="","",INDEX('Raw Data'!$F:$F,$X42)) | E42: =IF($Y42="","",IF(INDEX('Flight Rates'!$K:$K,$Y42)="","",INDEX('Flight Rates'!$K:$K,$Y42)+N($T42)+N($U42))) | F42: =IF($Y42="","",IF(INDEX('Flight Rates'!$L:$L,$Y42)="","",INDEX('Flight Rates'!$L:$L,$Y42)+N($T42)+N($U42))) | T42: =IF($Y42="","",N(INDEX('Flight Rates'!$S:$S,$Y42))) | U42: =IF(OR($Y42="",$C42="No tariff",$C42="No rate"),"",IFERROR(N(INDEX('Add-on Rates'!$C:$C,MATCH($A42,'Add-on Rates'!$A:$A,0))),0)) | X42: =IFERROR(SMALL('Raw Data'!$O$2:$O$1680,31),"") | Y42: =IF($X42="","",IFERROR(MATCH($B$3&"|"&$G$3&"|"&$B42&"|"&$D42,'Flight Rates'!$A:$A,0),"")) | Z42: =IF($Y42="","",INDEX('Flight Rates'!$P:$P,$Y42))
A43: =IF($X43="","",INDEX('Raw Data'!$D:$D,$X43)) | B43: =IF($X43="","",INDEX('Raw Data'!$E:$E,$X43)) | C43: =IF($X43="","",IF($Y43="","Not linked",IF(INDEX('Flight Rates'!$G:$G,$Y43)<>"",INDEX('Flight Rates'!$G:$G,$Y43),IF($Z43="NO TARIFF LOADED","No tariff","No rate")))) | D43: =IF($X43="","",INDEX('Raw Data'!$F:$F,$X43)) | E43: =IF($Y43="","",IF(INDEX('Flight Rates'!$K:$K,$Y43)="","",INDEX('Flight Rates'!$K:$K,$Y43)+N($T43)+N($U43))) | F43: =IF($Y43="","",IF(INDEX('Flight Rates'!$L:$L,$Y43)="","",INDEX('Flight Rates'!$L:$L,$Y43)+N($T43)+N($U43))) | T43: =IF($Y43="","",N(INDEX('Flight Rates'!$S:$S,$Y43))) | U43: =IF(OR($Y43="",$C43="No tariff",$C43="No rate"),"",IFERROR(N(INDEX('Add-on Rates'!$C:$C,MATCH($A43,'Add-on Rates'!$A:$A,0))),0)) | X43: =IFERROR(SMALL('Raw Data'!$O$2:$O$1680,32),"") | Y43: =IF($X43="","",IFERROR(MATCH($B$3&"|"&$G$3&"|"&$B43&"|"&$D43,'Flight Rates'!$A:$A,0),"")) | Z43: =IF($Y43="","",INDEX('Flight Rates'!$P:$P,$Y43))
...

Sheet Add-on Rates
A1: Airline code (as in Raw Data) | B1: Airline | C1: Add-on ₹/kg | D1: Includes
A2: AIRINDIA | B2: Air India / Air India Express | C2: 15.51 | D2: X-ray, TSP, handling etc. (approx.)
A3: INDIGO | B3: IndiGo | C3: 17.95 | D3: X-ray, TSP, handling etc. (approx.)
A4: AKASA | B4: Akasa Air | C4: 13.52 | D4: X-ray, TSP, handling etc. (approx.)
A5: SPICEJET | B5: SpiceJet | C5: 24 | D5: X-ray, TSP, handling etc. (approx.)
A8: Edit the yellow ₹/kg values when your add-on costs change - the Dashboard's CPKG columns update immediately (no need to re-run link_rates.py).

Sheet Raw Data
A1: Origin | B1: Destination | C1: OD Pair | D1: Airline | E1: Flight No | F1: Dep Time | G1: Mon | H1: Tue | I1: Wed | J1: Thu | K1: Fri | L1: Sat | M1: Sun | N1: Weekly Freq | O1: MatchRow (helper - do not edit)
A2: AMD | B2: BBI | C2: AMD-BBI | D2: INDIGO | E2: 6E6237 | F2: 17:55 | G2: 1 | H2: 0 | I2: 1 | J2: 0 | K2: 1 | L2: 1 | M2: 1 | N2: =SUM(G2:M2) -> 5 | O2: =IF(AND($A2=Dashboard!$B$3,$B2=Dashboard!$G$3,$D2<>"NO_SERVICE"),ROW(),"")
A3: AMD | B3: CJB | C3: AMD-CJB | D3: NO_SERVICE | G3: 0 | H3: 0 | I3: 0 | J3: 0 | K3: 0 | L3: 0 | M3: 0 | N3: =SUM(G3:M3) -> 0 | O3: =IF(AND($A3=Dashboard!$B$3,$B3=Dashboard!$G$3,$D3<>"NO_SERVICE"),ROW(),"")
A4: AMD | B4: COK | C4: AMD-COK | D4: INDIGO | E4: 6E6391 | F4: 10:55 | G4: 1 | H4: 0 | I4: 1 | J4: 0 | K4: 1 | L4: 1 | M4: 1 | N4: =SUM(G4:M4) -> 5 | O4: =IF(AND($A4=Dashboard!$B$3,$B4=Dashboard!$G$3,$D4<>"NO_SERVICE"),ROW(),"")
A5: AMD | B5: GOI | C5: AMD-GOI | D5: INDIGO | E5: 6E6345 | F5: 16:15 | G5: 1 | H5: 0 | I5: 1 | J5: 1 | K5: 1 | L5: 1 | M5: 1 | N5: =SUM(G5:M5) -> 6 | O5: =IF(AND($A5=Dashboard!$B$3,$B5=Dashboard!$G$3,$D5<>"NO_SERVICE"),ROW(),"")
A6: AMD | B6: GOI | C6: AMD-GOI | D6: INDIGO | E6: 6E992 | F6: 19:30 | G6: 1 | H6: 1 | I6: 0 | J6: 1 | K6: 1 | L6: 0 | M6: 1 | N6: =SUM(G6:M6) -> 5 | O6: =IF(AND($A6=Dashboard!$B$3,$B6=Dashboard!$G$3,$D6<>"NO_SERVICE"),ROW(),"")
A7: AMD | B7: GAU | C7: AMD-GAU | D7: INDIGO | E7: 6E6441 | F7: 06:05 | G7: 1 | H7: 1 | I7: 1 | J7: 1 | K7: 1 | L7: 1 | M7: 1 | N7: =SUM(G7:M7) -> 7 | O7: =IF(AND($A7=Dashboard!$B$3,$B7=Dashboard!$G$3,$D7<>"NO_SERVICE"),ROW(),"")
A8: AMD | B8: IDR | C8: AMD-IDR | D8: INDIGO | E8: 6E7173 | F8: 06:55 | G8: 1 | H8: 1 | I8: 1 | J8: 1 | K8: 1 | L8: 1 | M8: 1 | N8: =SUM(G8:M8) -> 7 | O8: =IF(AND($A8=Dashboard!$B$3,$B8=Dashboard!$G$3,$D8<>"NO_SERVICE"),ROW(),"")
A9: AMD | B9: IDR | C9: AMD-IDR | D9: INDIGO | E9: 6E7187 | F9: 20:10 | G9: 1 | H9: 1 | I9: 1 | J9: 1 | K9: 1 | L9: 1 | M9: 1 | N9: =SUM(G9:M9) -> 7 | O9: =IF(AND($A9=Dashboard!$B$3,$B9=Dashboard!$G$3,$D9<>"NO_SERVICE"),ROW(),"")
A10: AMD | B10: IXB | C10: AMD-IXB | D10: AKASA | E10: QP1569 | F10: 11:30 | G10: 1 | H10: 0 | I10: 1 | J10: 0 | K10: 1 | L10: 0 | M10: 1 | N10: =SUM(G10:M10) -> 4 | O10: =IF(AND($A10=Dashboard!$B$3,$B10=Dashboard!$G$3,$D10<>"NO_SERVICE"),ROW(),"")
A11: AMD | B11: IXB | C11: AMD-IXB | D11: AKASA | E11: QP1903 | F11: 11:15 | G11: 0 | H11: 1 | I11: 0 | J11: 1 | K11: 0 | L11: 0 | M11: 0 | N11: =SUM(G11:M11) -> 2 | O11: =IF(AND($A11=Dashboard!$B$3,$B11=Dashboard!$G$3,$D11<>"NO_SERVICE"),ROW(),"")
A12: AMD | B12: IXM | C12: AMD-IXM | D12: NO_SERVICE | G12: 0 | H12: 0 | I12: 0 | J12: 0 | K12: 0 | L12: 0 | M12: 0 | N12: =SUM(G12:M12) -> 0 | O12: =IF(AND($A12=Dashboard!$B$3,$B12=Dashboard!$G$3,$D12<>"NO_SERVICE"),ROW(),"")
A13: AMD | B13: IXZ | C13: AMD-IXZ | D13: NO_SERVICE | G13: 0 | H13: 0 | I13: 0 | J13: 0 | K13: 0 | L13: 0 | M13: 0 | N13: =SUM(G13:M13) -> 0 | O13: =IF(AND($A13=Dashboard!$B$3,$B13=Dashboard!$G$3,$D13<>"NO_SERVICE"),ROW(),"")
A14: AMD | B14: JAI | C14: AMD-JAI | D14: INDIGO | E14: 6E7114 | F14: 06:15 | G14: 1 | H14: 1 | I14: 1 | J14: 1 | K14: 1 | L14: 1 | M14: 1 | N14: =SUM(G14:M14) -> 7 | O14: =IF(AND($A14=Dashboard!$B$3,$B14=Dashboard!$G$3,$D14<>"NO_SERVICE"),ROW(),"")
A15: AMD | B15: JAI | C15: AMD-JAI | D15: INDIGO | E15: 6E7261 | F15: 15:40 | G15: 1 | H15: 1 | I15: 1 | J15: 1 | K15: 1 | L15: 1 | M15: 1 | N15: =SUM(G15:M15) -> 7 | O15: =IF(AND($A15=Dashboard!$B$3,$B15=Dashboard!$G$3,$D15<>"NO_SERVICE"),ROW(),"")
A16: AMD | B16: JAI | C16: AMD-JAI | D16: INDIGO | E16: 6E7131 | F16: 21:05 | G16: 1 | H16: 1 | I16: 1 | J16: 1 | K16: 1 | L16: 1 | M16: 1 | N16: =SUM(G16:M16) -> 7 | O16: =IF(AND($A16=Dashboard!$B$3,$B16=Dashboard!$G$3,$D16<>"NO_SERVICE"),ROW(),"")
A17: AMD | B17: LKO | C17: AMD-LKO | D17: INDIGO | E17: 6E6244 | F17: 08:15 | G17: 1 | H17: 1 | I17: 0 | J17: 1 | K17: 1 | L17: 1 | M17: 1 | N17: =SUM(G17:M17) -> 6 | O17: =IF(AND($A17=Dashboard!$B$3,$B17=Dashboard!$G$3,$D17<>"NO_SERVICE"),ROW(),"")
A18: AMD | B18: LKO | C18: AMD-LKO | D18: INDIGO | E18: 6E935 | F18: 14:15 | G18: 0 | H18: 1 | I18: 0 | J18: 0 | K18: 1 | L18: 1 | M18: 1 | N18: =SUM(G18:M18) -> 4 | O18: =IF(AND($A18=Dashboard!$B$3,$B18=Dashboard!$G$3,$D18<>"NO_SERVICE"),ROW(),"")
A19: AMD | B19: NAG | C19: AMD-NAG | D19: INDIGO | E19: 6E7247 | F19: 05:40 | G19: 1 | H19: 1 | I19: 1 | J19: 1 | K19: 1 | L19: 1 | M19: 1 | N19: =SUM(G19:M19) -> 7 | O19: =IF(AND($A19=Dashboard!$B$3,$B19=Dashboard!$G$3,$D19<>"NO_SERVICE"),ROW(),"")
A20: AMD | B20: NAG | C20: AMD-NAG | D20: INDIGO | E20: 6E7502 | F20: 18:55 | G20: 1 | H20: 1 | I20: 1 | J20: 1 | K20: 1 | L20: 1 | M20: 1 | N20: =SUM(G20:M20) -> 7 | O20: =IF(AND($A20=Dashboard!$B$3,$B20=Dashboard!$G$3,$D20<>"NO_SERVICE"),ROW(),"")
A21: AMD | B21: PAT | C21: AMD-PAT | D21: INDIGO | E21: 6E921 | F21: 10:40 | G21: 1 | H21: 1 | I21: 0 | J21: 1 | K21: 1 | L21: 1 | M21: 1 | N21: =SUM(G21:M21) -> 6 | O21: =IF(AND($A21=Dashboard!$B$3,$B21=Dashboard!$G$3,$D21<>"NO_SERVICE"),ROW(),"")
A22: AMD | B22: PAT | C22: AMD-PAT | D22: INDIGO | E22: 6E2524 | F22: 18:30 | G22: 0 | H22: 0 | I22: 1 | J22: 0 | K22: 0 | L22: 0 | M22: 0 | N22: =SUM(G22:M22) -> 1 | O22: =IF(AND($A22=Dashboard!$B$3,$B22=Dashboard!$G$3,$D22<>"NO_SERVICE"),ROW(),"")
A23: AMD | B23: IXR | C23: AMD-IXR | D23: INDIGO | E23: 6E6493 | F23: 11:10 | G23: 1 | H23: 1 | I23: 1 | J23: 1 | K23: 1 | L23: 1 | M23: 1 | N23: =SUM(G23:M23) -> 7 | O23: =IF(AND($A23=Dashboard!$B$3,$B23=Dashboard!$G$3,$D23<>"NO_SERVICE"),ROW(),"")
A24: AMD | B24: RPR | C24: AMD-RPR | D24: INDIGO | E24: 6E261 | F24: 11:30 | G24: 1 | H24: 1 | I24: 1 | J24: 1 | K24: 1 | L24: 1 | M24: 1 | N24: =SUM(G24:M24) -> 7 | O24: =IF(AND($A24=Dashboard!$B$3,$B24=Dashboard!$G$3,$D24<>"NO_SERVICE"),ROW(),"")
A25: AMD | B25: IXC | C25: AMD-IXC | D25: INDIGO | E25: 6E6375 | F25: 07:40 | G25: 0 | H25: 1 | I25: 1 | J25: 1 | K25: 1 | L25: 1 | M25: 1 | N25: =SUM(G25:M25) -> 6 | O25: =IF(AND($A25=Dashboard!$B$3,$B25=Dashboard!$G$3,$D25<>"NO_SERVICE"),ROW(),"")
A26: AMD | B26: IXC | C26: AMD-IXC | D26: INDIGO | E26: 6E6506 | F26: 21:45 | G26: 1 | H26: 0 | I26: 0 | J26: 0 | K26: 0 | L26: 0 | M26: 0 | N26: =SUM(G26:M26) -> 1 | O26: =IF(AND($A26=Dashboard!$B$3,$B26=Dashboard!$G$3,$D26<>"NO_SERVICE"),ROW(),"")
A27: AMD | B27: UDR | C27: AMD-UDR | D27: NO_SERVICE | G27: 0 | H27: 0 | I27: 0 | J27: 0 | K27: 0 | L27: 0 | M27: 0 | N27: =SUM(G27:M27) -> 0 | O27: =IF(AND($A27=Dashboard!$B$3,$B27=Dashboard!$G$3,$D27<>"NO_SERVICE"),ROW(),"")
A28: AMD | B28: SXR | C28: AMD-SXR | D28: INDIGO | E28: 6E6164 | F28: 07:55 | G28: 0 | H28: 0 | I28: 1 | J28: 0 | K28: 1 | L28: 0 | M28: 1 | N28: =SUM(G28:M28) -> 3 | O28: =IF(AND($A28=Dashboard!$B$3,$B28=Dashboard!$G$3,$D28<>"NO_SERVICE"),ROW(),"")
A29: AMD | B29: IXJ | C29: AMD-IXJ | D29: INDIGO | E29: 6E6687 | F29: 09:00 | G29: 1 | H29: 1 | I29: 1 | J29: 1 | K29: 1 | L29: 1 | M29: 1 | N29: =SUM(G29:M29) -> 7 | O29: =IF(AND($A29=Dashboard!$B$3,$B29=Dashboard!$G$3,$D29<>"NO_SERVICE"),ROW(),"")
A30: AMD | B30: TVM | C30: AMD-TVM | D30: NO_SERVICE | G30: 0 | H30: 0 | I30: 0 | J30: 0 | K30: 0 | L30: 0 | M30: 0 | N30: =SUM(G30:M30) -> 0 | O30: =IF(AND($A30=Dashboard!$B$3,$B30=Dashboard!$G$3,$D30<>"NO_SERVICE"),ROW(),"")
A31: AMD | B31: VTZ | C31: AMD-VTZ | D31: INDIGO | E31: 6E879 | F31: 08:44 | G31: 1 | H31: 1 | I31: 1 | J31: 1 | K31: 1 | L31: 1 | M31: 1 | N31: =SUM(G31:M31) -> 7 | O31: =IF(AND($A31=Dashboard!$B$3,$B31=Dashboard!$G$3,$D31<>"NO_SERVICE"),ROW(),"")
A32: AMD | B32: IMF | C32: AMD-IMF | D32: NO_SERVICE | G32: 0 | H32: 0 | I32: 0 | J32: 0 | K32: 0 | L32: 0 | M32: 0 | N32: =SUM(G32:M32) -> 0 | O32: =IF(AND($A32=Dashboard!$B$3,$B32=Dashboard!$G$3,$D32<>"NO_SERVICE"),ROW(),"")
A33: AMD | B33: BHO | C33: AMD-BHO | D33: INDIGO | E33: 6E7525 | F33: 05:50 | G33: 1 | H33: 1 | I33: 1 | J33: 1 | K33: 1 | L33: 1 | M33: 1 | N33: =SUM(G33:M33) -> 7 | O33: =IF(AND($A33=Dashboard!$B$3,$B33=Dashboard!$G$3,$D33<>"NO_SERVICE"),ROW(),"")
A34: AMD | B34: VNS | C34: AMD-VNS | D34: INDIGO | E34: 6E6805 | F34: 14:45 | G34: 1 | H34: 1 | I34: 1 | J34: 1 | K34: 1 | L34: 1 | M34: 1 | N34: =SUM(G34:M34) -> 7 | O34: =IF(AND($A34=Dashboard!$B$3,$B34=Dashboard!$G$3,$D34<>"NO_SERVICE"),ROW(),"")
A35: AMD | B35: IXL | C35: AMD-IXL | D35: NO_SERVICE | G35: 0 | H35: 0 | I35: 0 | J35: 0 | K35: 0 | L35: 0 | M35: 0 | N35: =SUM(G35:M35) -> 0 | O35: =IF(AND($A35=Dashboard!$B$3,$B35=Dashboard!$G$3,$D35<>"NO_SERVICE"),ROW(),"")
A36: AMD | B36: VGA | C36: AMD-VGA | D36: NO_SERVICE | G36: 0 | H36: 0 | I36: 0 | J36: 0 | K36: 0 | L36: 0 | M36: 0 | N36: =SUM(G36:M36) -> 0 | O36: =IF(AND($A36=Dashboard!$B$3,$B36=Dashboard!$G$3,$D36<>"NO_SERVICE"),ROW(),"")
A37: AMD | B37: TRZ | C37: AMD-TRZ | D37: NO_SERVICE | G37: 0 | H37: 0 | I37: 0 | J37: 0 | K37: 0 | L37: 0 | M37: 0 | N37: =SUM(G37:M37) -> 0 | O37: =IF(AND($A37=Dashboard!$B$3,$B37=Dashboard!$G$3,$D37<>"NO_SERVICE"),ROW(),"")
A38: BLR | B38: BBI | C38: BLR-BBI | D38: INDIGO | E38: 6E702 | F38: 07:30 | G38: 1 | H38: 1 | I38: 1 | J38: 1 | K38: 1 | L38: 1 | M38: 1 | N38: =SUM(G38:M38) -> 7 | O38: =IF(AND($A38=Dashboard!$B$3,$B38=Dashboard!$G$3,$D38<>"NO_SERVICE"),ROW(),"")
A39: BLR | B39: BBI | C39: BLR-BBI | D39: INDIGO | E39: 6E6535 | F39: 11:40 | G39: 0 | H39: 1 | I39: 0 | J39: 1 | K39: 0 | L39: 1 | M39: 0 | N39: =SUM(G39:M39) -> 3 | O39: =IF(AND($A39=Dashboard!$B$3,$B39=Dashboard!$G$3,$D39<>"NO_SERVICE"),ROW(),"")
A40: BLR | B40: BBI | C40: BLR-BBI | D40: INDIGO | E40: 6E411 | F40: 20:05 | G40: 1 | H40: 1 | I40: 1 | J40: 1 | K40: 1 | L40: 1 | M40: 1 | N40: =SUM(G40:M40) -> 7 | O40: =IF(AND($A40=Dashboard!$B$3,$B40=Dashboard!$G$3,$D40<>"NO_SERVICE"),ROW(),"")
...

Sheet OD Pair Summary
A1: OD Pair | B1: Airline | C1: Total Weekly Flights
A2: AMD-BBI | B2: IndiGo | C2: =SUMIFS('Raw Data'!$N$2:$N$1680,'Raw Data'!$C$2:$C$1680,A2,'Raw Data'!$D$2:$D$1680,"INDIGO",'Raw Data'!$E$2:$E$1680,"6E*") -> 5
A3: AMD-CJB | B3: NO_SERVICE | C3: =SUMIFS('Raw Data'!$N$2:$N$1680,'Raw Data'!$C$2:$C$1680,A3,'Raw Data'!$D$2:$D$1680,B3) -> 0
A4: AMD-COK | B4: IndiGo | C4: =SUMIFS('Raw Data'!$N$2:$N$1680,'Raw Data'!$C$2:$C$1680,A4,'Raw Data'!$D$2:$D$1680,"INDIGO",'Raw Data'!$E$2:$E$1680,"6E*") -> 5
A5: AMD-GOI | B5: IndiGo | C5: =SUMIFS('Raw Data'!$N$2:$N$1680,'Raw Data'!$C$2:$C$1680,A5,'Raw Data'!$D$2:$D$1680,"INDIGO",'Raw Data'!$E$2:$E$1680,"6E*") -> 11
A6: AMD-GAU | B6: IndiGo | C6: =SUMIFS('Raw Data'!$N$2:$N$1680,'Raw Data'!$C$2:$C$1680,A6,'Raw Data'!$D$2:$D$1680,"INDIGO",'Raw Data'!$E$2:$E$1680,"6E*") -> 7
A7: AMD-IDR | B7: IndiGo | C7: =SUMIFS('Raw Data'!$N$2:$N$1680,'Raw Data'!$C$2:$C$1680,A7,'Raw Data'!$D$2:$D$1680,"INDIGO",'Raw Data'!$E$2:$E$1680,"6E*") -> 14
A8: AMD-IXB | B8: Akasa Air | C8: =SUMIFS('Raw Data'!$N$2:$N$1680,'Raw Data'!$C$2:$C$1680,A8,'Raw Data'!$D$2:$D$1680,"AKASA",'Raw Data'!$E$2:$E$1680,"QP*") -> 6
A9: AMD-IXM | B9: NO_SERVICE | C9: =SUMIFS('Raw Data'!$N$2:$N$1680,'Raw Data'!$C$2:$C$1680,A9,'Raw Data'!$D$2:$D$1680,B9) -> 0
A10: AMD-IXZ | B10: NO_SERVICE | C10: =SUMIFS('Raw Data'!$N$2:$N$1680,'Raw Data'!$C$2:$C$1680,A10,'Raw Data'!$D$2:$D$1680,B10) -> 0
A11: AMD-JAI | B11: IndiGo | C11: =SUMIFS('Raw Data'!$N$2:$N$1680,'Raw Data'!$C$2:$C$1680,A11,'Raw Data'!$D$2:$D$1680,"INDIGO",'Raw Data'!$E$2:$E$1680,"6E*") -> 21
A12: AMD-LKO | B12: IndiGo | C12: =SUMIFS('Raw Data'!$N$2:$N$1680,'Raw Data'!$C$2:$C$1680,A12,'Raw Data'!$D$2:$D$1680,"INDIGO",'Raw Data'!$E$2:$E$1680,"6E*") -> 10
A13: AMD-NAG | B13: IndiGo | C13: =SUMIFS('Raw Data'!$N$2:$N$1680,'Raw Data'!$C$2:$C$1680,A13,'Raw Data'!$D$2:$D$1680,"INDIGO",'Raw Data'!$E$2:$E$1680,"6E*") -> 14
A14: AMD-PAT | B14: IndiGo | C14: =SUMIFS('Raw Data'!$N$2:$N$1680,'Raw Data'!$C$2:$C$1680,A14,'Raw Data'!$D$2:$D$1680,"INDIGO",'Raw Data'!$E$2:$E$1680,"6E*") -> 7
A15: AMD-IXR | B15: IndiGo | C15: =SUMIFS('Raw Data'!$N$2:$N$1680,'Raw Data'!$C$2:$C$1680,A15,'Raw Data'!$D$2:$D$1680,"INDIGO",'Raw Data'!$E$2:$E$1680,"6E*") -> 7
A16: AMD-RPR | B16: IndiGo | C16: =SUMIFS('Raw Data'!$N$2:$N$1680,'Raw Data'!$C$2:$C$1680,A16,'Raw Data'!$D$2:$D$1680,"INDIGO",'Raw Data'!$E$2:$E$1680,"6E*") -> 7
A17: AMD-IXC | B17: IndiGo | C17: =SUMIFS('Raw Data'!$N$2:$N$1680,'Raw Data'!$C$2:$C$1680,A17,'Raw Data'!$D$2:$D$1680,"INDIGO",'Raw Data'!$E$2:$E$1680,"6E*") -> 7
A18: AMD-UDR | B18: NO_SERVICE | C18: =SUMIFS('Raw Data'!$N$2:$N$1680,'Raw Data'!$C$2:$C$1680,A18,'Raw Data'!$D$2:$D$1680,B18) -> 0
A19: AMD-SXR | B19: IndiGo | C19: =SUMIFS('Raw Data'!$N$2:$N$1680,'Raw Data'!$C$2:$C$1680,A19,'Raw Data'!$D$2:$D$1680,"INDIGO",'Raw Data'!$E$2:$E$1680,"6E*") -> 3
A20: AMD-IXJ | B20: IndiGo | C20: =SUMIFS('Raw Data'!$N$2:$N$1680,'Raw Data'!$C$2:$C$1680,A20,'Raw Data'!$D$2:$D$1680,"INDIGO",'Raw Data'!$E$2:$E$1680,"6E*") -> 7
A21: AMD-TVM | B21: NO_SERVICE | C21: =SUMIFS('Raw Data'!$N$2:$N$1680,'Raw Data'!$C$2:$C$1680,A21,'Raw Data'!$D$2:$D$1680,B21) -> 0
A22: AMD-VTZ | B22: IndiGo | C22: =SUMIFS('Raw Data'!$N$2:$N$1680,'Raw Data'!$C$2:$C$1680,A22,'Raw Data'!$D$2:$D$1680,"INDIGO",'Raw Data'!$E$2:$E$1680,"6E*") -> 7
A23: AMD-IMF | B23: NO_SERVICE | C23: =SUMIFS('Raw Data'!$N$2:$N$1680,'Raw Data'!$C$2:$C$1680,A23,'Raw Data'!$D$2:$D$1680,B23) -> 0
A24: AMD-BHO | B24: IndiGo | C24: =SUMIFS('Raw Data'!$N$2:$N$1680,'Raw Data'!$C$2:$C$1680,A24,'Raw Data'!$D$2:$D$1680,"INDIGO",'Raw Data'!$E$2:$E$1680,"6E*") -> 7
A25: AMD-VNS | B25: IndiGo | C25: =SUMIFS('Raw Data'!$N$2:$N$1680,'Raw Data'!$C$2:$C$1680,A25,'Raw Data'!$D$2:$D$1680,"INDIGO",'Raw Data'!$E$2:$E$1680,"6E*") -> 7
A26: AMD-IXL | B26: NO_SERVICE | C26: =SUMIFS('Raw Data'!$N$2:$N$1680,'Raw Data'!$C$2:$C$1680,A26,'Raw Data'!$D$2:$D$1680,B26) -> 0
A27: AMD-VGA | B27: NO_SERVICE | C27: =SUMIFS('Raw Data'!$N$2:$N$1680,'Raw Data'!$C$2:$C$1680,A27,'Raw Data'!$D$2:$D$1680,B27) -> 0
A28: AMD-TRZ | B28: NO_SERVICE | C28: =SUMIFS('Raw Data'!$N$2:$N$1680,'Raw Data'!$C$2:$C$1680,A28,'Raw Data'!$D$2:$D$1680,B28) -> 0
A29: BLR-BBI | B29: IndiGo | C29: =SUMIFS('Raw Data'!$N$2:$N$1680,'Raw Data'!$C$2:$C$1680,A29,'Raw Data'!$D$2:$D$1680,"INDIGO",'Raw Data'!$E$2:$E$1680,"6E*") -> 17
A30: BLR-BBI | B30: Akasa Air | C30: =SUMIFS('Raw Data'!$N$2:$N$1680,'Raw Data'!$C$2:$C$1680,A30,'Raw Data'!$D$2:$D$1680,"AKASA",'Raw Data'!$E$2:$E$1680,"QP*") -> 7
A31: BLR-BBI | B31: Air India Express | C31: =SUMIFS('Raw Data'!$N$2:$N$1680,'Raw Data'!$C$2:$C$1680,A31,'Raw Data'!$D$2:$D$1680,"AIRINDIA",'Raw Data'!$E$2:$E$1680,"IX*") -> 7
A32: BLR-CJB | B32: IndiGo | C32: =SUMIFS('Raw Data'!$N$2:$N$1680,'Raw Data'!$C$2:$C$1680,A32,'Raw Data'!$D$2:$D$1680,"INDIGO",'Raw Data'!$E$2:$E$1680,"6E*") -> 22
A33: BLR-GOI | B33: IndiGo | C33: =SUMIFS('Raw Data'!$N$2:$N$1680,'Raw Data'!$C$2:$C$1680,A33,'Raw Data'!$D$2:$D$1680,"INDIGO",'Raw Data'!$E$2:$E$1680,"6E*") -> 35
A34: BLR-GOI | B34: Alliance Air | C34: =SUMIFS('Raw Data'!$N$2:$N$1680,'Raw Data'!$C$2:$C$1680,A34,'Raw Data'!$D$2:$D$1680,"ALLIANCE",'Raw Data'!$E$2:$E$1680,"9I*") -> 0
A35: BLR-GOI | B35: Air India Express | C35: =SUMIFS('Raw Data'!$N$2:$N$1680,'Raw Data'!$C$2:$C$1680,A35,'Raw Data'!$D$2:$D$1680,"AIRINDIA",'Raw Data'!$E$2:$E$1680,"IX*") -> 10
A36: BLR-IDR | B36: IndiGo | C36: =SUMIFS('Raw Data'!$N$2:$N$1680,'Raw Data'!$C$2:$C$1680,A36,'Raw Data'!$D$2:$D$1680,"INDIGO",'Raw Data'!$E$2:$E$1680,"6E*") -> 18
A37: BLR-IDR | B37: Air India Express | C37: =SUMIFS('Raw Data'!$N$2:$N$1680,'Raw Data'!$C$2:$C$1680,A37,'Raw Data'!$D$2:$D$1680,"AIRINDIA",'Raw Data'!$E$2:$E$1680,"IX*") -> 7
A38: BLR-IXB | B38: IndiGo | C38: =SUMIFS('Raw Data'!$N$2:$N$1680,'Raw Data'!$C$2:$C$1680,A38,'Raw Data'!$D$2:$D$1680,"INDIGO",'Raw Data'!$E$2:$E$1680,"6E*") -> 4
A39: BLR-IXB | B39: Akasa Air | C39: =SUMIFS('Raw Data'!$N$2:$N$1680,'Raw Data'!$C$2:$C$1680,A39,'Raw Data'!$D$2:$D$1680,"AKASA",'Raw Data'!$E$2:$E$1680,"QP*") -> 4
A40: BLR-IXB | B40: Air India Express | C40: =SUMIFS('Raw Data'!$N$2:$N$1680,'Raw Data'!$C$2:$C$1680,A40,'Raw Data'!$D$2:$D$1680,"AIRINDIA",'Raw Data'!$E$2:$E$1680,"IX*") -> 13
...

Sheet Progress
A1: OD Pairs Completed | B1: 272 of 272
A3: Origin | B3: Destination
A4: AMD | B4: BBI
A5: AMD | B5: CJB
A6: AMD | B6: COK
A7: AMD | B7: GOI
A8: AMD | B8: GAU
A9: AMD | B9: IDR
A10: AMD | B10: IXB
A11: AMD | B11: IXM
A12: AMD | B12: IXZ
A13: AMD | B13: JAI
... A275: PNQ | B275: MAA

Sheet Lists
A1: Code | B1: Name | D1: ATC Codes | F1: Destination Codes
A2: AMD | B2: Ahmedabad | D2: AMD | F2: AMD
A3: BLR | B3: Bengaluru | D3: BLR | F3: BLR
A4: BOM | B4: Mumbai | D4: BOM | F4: BOM
A5: CCU | B5: Kolkata | D5: CCU | F5: CCU
A6: DEL | B6: Delhi | D6: DEL | F6: DEL
A7: HYD | B7: Hyderabad | D7: HYD | F7: HYD
A8: MAA | B8: Chennai | D8: MAA | F8: MAA
A9: PNQ | B9: Pune | D9: PNQ | F9: PNQ
A10: BBI | B10: Bhubaneswar | F10: BBI
A11: CJB | B11: Coimbatore | F11: CJB
A12: COK | B12: Kochi | F12: COK
A13: GOI | B13: Goa | F13: GOI
A14: GAU | B14: Guwahati | F14: GAU
A15: IDR | B15: Indore | F15: IDR
A16: IXB | B16: Bagdogra | F16: IXB
A17: IXM | B17: Madurai | F17: IXM
A18: IXZ | B18: Port Blair | F18: IXZ
A19: JAI | B19: Jaipur | F19: JAI
A20: LKO | B20: Lucknow | F20: LKO
A21: NAG | B21: Nagpur | F21: NAG
... A36: TRZ | B36: Tiruchirappalli | F36: TRZ

Sheet Network Surcharges
A1: Airline | B1: Applies To | C1: Station / Route | D1: Rs per kg | E1: Valid From | F1: Valid To | G1: Reason / Source | H1: Active (Y/N) | I1: Dashboard Label | K1: How to use
A2: IndiGo | B2: All | D2: 4 | E2: 46114 | G2: Fuel surcharge, PAN India on chargeable weight (IndiGo footnotes) | H2: Y | I2: Fuel | K2: Surcharges from the tariff NOTES / FOOTNOTES that apply across many routes.
A3: Air India | B3: All | D3: 5 | E3: 46115 | G3: SS surcharge on all domestic shipments (AI Notation 1(iv)) | H3: Y | I3: SS | K3: Route- and flight-specific surcharges are read from the database automatically - don't list them here.
A4: Air India | B4: Origin | C4: BOM | D4: 8 | E4: 46254 | G4: Additional surcharge ex-BOM to India (AI Notation 1(viii)) | H4: Y | I4: Ex-BOM | K4: Airline: IndiGo or Air India (Air India also covers Air India Express / IX flights).
A5: Air India | B5: Destination | C5: BOM | D5: 6 | E5: 46254 | G5: Additional surcharge India to BOM (AI Notation 1(viii)) | H5: Y | I5: To-BOM | K5: Applies To: All | Origin | Destination | Route. Station / Route: e.g. BOM, or DEL-COK for Route.
A6: Air India | B6: Origin | C6: TRV | D6: 2 | E6: 46249 | F6: 46341 | G6: Lotus Flower surcharge ex-TRV (AI Notation 1(vii)) | H6: Y | I6: Lotus | K6: Leave Valid To blank for 'until further notice'. Set Active to N to switch a row off.
A7: Air India | B7: Route | C7: CCU-COK | D7: 5 | E7: 46241 | F7: 46265 | G7: Onam surcharge (AI Notation 1(vi)) | H7: Y | I7: Onam | K7: Dashboard Label: the short name shown in the Dashboard's Surcharge Reason column.
A8: Air India | B8: Route | C8: DEL-COK | D8: 5 | E8: 46241 | F8: 46265 | G8: Onam surcharge (AI Notation 1(vi)) | H8: Y | I8: Onam | K8: After editing, close the workbook and run link_rates.py again.
A9: Air India | B9: Route | C9: JAI-COK | D9: 5 | E9: 46241 | F9: 46265 | G9: Onam surcharge (AI Notation 1(vi)) | H9: Y | I9: Onam
A10: Air India | B10: Route | C10: IXC-COK | D10: 5 | E10: 46241 | F10: 46265 | G10: Onam surcharge (AI Notation 1(vi)) | H10: Y | I10: Onam
A11: Air India | B11: Route | C11: LKO-COK | D11: 5 | E11: 46241 | F11: 46265 | G11: Onam surcharge (AI Notation 1(vi)) | H11: Y | I11: Onam

Sheet Flight Rates
A1: Key | B1: Origin | C1: Destination | D1: Airline | E1: Flight No | F1: Dep Time | G1: Product | H1: Effective Date | I1: Min | J1: N | K1: 45+ | L1: 100+ | M1: 300+ | N1: 500+ | O1: 1000+ | P1: Status | Q1: Tariff Condition | R1: Match Note | S1: Surcharge Rs/kg | T1: Surcharge Reason | U1: Surcharge Summary | W1: Rate info
A2: AMD|BBI|6E6237|17:55 | B2: AMD | C2: BBI | D2: INDIGO | E2: 6E6237 | F2: 17:55 | G2: GCR | H2: 46250 | I2: 1800 | J2: 61 | K2: 49 | L2: 43 | P2: OK | R2: Route rate (all flights) | S2: 4 | T2: Rs 4 Fuel surcharge, PAN India on chargeable weight (IndiGo footnotes) | U2: Fuel ₹4 | W2: Refreshed | X2: 46294.222
A3: AMD|COK|6E6391|10:55 | B3: AMD | C3: COK | D3: INDIGO | E3: 6E6391 | F3: 10:55 | G3: GCR | H3: 46250 | I3: 1800 | J3: 66 | K3: 54 | L3: 47 | P3: OK | R3: Route rate (all flights) | S3: 4 | T3: Rs 4 Fuel surcharge, PAN India on chargeable weight (IndiGo footnotes) | U3: Fuel ₹4 | W3: Rates as of | X3: 46294
A4: AMD|GOI|6E6345|16:15 | B4: AMD | C4: GOI | D4: INDIGO | E4: 6E6345 | F4: 16:15 | G4: GCR | H4: 46250 | I4: 1800 | J4: 64 | K4: 52 | L4: 45 | P4: OK | R4: Route rate (all flights) | S4: 4 | T4: Rs 4 Fuel surcharge, PAN India on chargeable weight (IndiGo footnotes) | U4: Fuel ₹4 | W4: IndiGo effective | X4: 46250
A5: AMD|GOI|6E992|19:30 | B5: AMD | C5: GOI | D5: INDIGO | E5: 6E992 | F5: 19:30 | G5: GCR | H5: 46250 | I5: 1800 | J5: 64 | K5: 52 | L5: 45 | P5: OK | R5: Route rate (all flights) | S5: 4 | T5: Rs 4 Fuel surcharge, PAN India on chargeable weight (IndiGo footnotes) | U5: Fuel ₹4 | W5: IndiGo file | X5: 8.1 6E Eff. 16th Aug 2026.xlsx
A6: AMD|GAU|6E6441|06:05 | B6: AMD | C6: GAU | D6: INDIGO | E6: 6E6441 | F6: 06:05 | G6: GCR | H6: 46250 | I6: 1800 | J6: 79 | P6: OK | R6: Route rate (all flights) | S6: 4 | T6: Rs 4 Fuel surcharge, PAN India on chargeable weight (IndiGo footnotes) | U6: Fuel ₹4 | W6: Air India effective | X6: 46254
A7: AMD|IDR|6E7173|06:55 | B7: AMD | C7: IDR | D7: INDIGO | E7: 6E7173 | F7: 06:55 | G7: GCR | H7: 46250 | I7: 1800 | J7: 64 | K7: 52 | L7: 45 | P7: OK | R7: Route rate (all flights) | S7: 4 | T7: Rs 4 Fuel surcharge, PAN India on chargeable weight (IndiGo footnotes) | U7: Fuel ₹4 | W7: Air India file | X7: 8.3 AI effective 20-Aug-26.xlsx
A8: AMD|IDR|6E7187|20:10 | B8: AMD | C8: IDR | D8: INDIGO | E8: 6E7187 | F8: 20:10 | G8: GCR | H8: 46250 | I8: 1800 | J8: 64 | K8: 52 | L8: 45 | P8: OK | R8: Route rate (all flights) | S8: 4 | T8: Rs 4 Fuel surcharge, PAN India on chargeable weight (IndiGo footnotes) | U8: Fuel ₹4
A9: AMD|IXB|QP1569|11:30 | B9: AMD | C9: IXB | D9: AKASA | E9: QP1569 | F9: 11:30 | P9: NO TARIFF LOADED | R9: This airline's tariff is not loaded in the database
A10: AMD|IXB|QP1903|11:15 | B10: AMD | C10: IXB | D10: AKASA | E10: QP1903 | F10: 11:15 | P10: NO TARIFF LOADED | R10: This airline's tariff is not loaded in the database
A11: AMD|JAI|6E7114|06:15 | B11: AMD | C11: JAI | D11: INDIGO | E11: 6E7114 | F11: 06:15 | G11: GCR | H11: 46250 | I11: 1800 | J11: 64 | K11: 52 | L11: 45 | P11: OK | R11: Route rate (all flights) | S11: 4 | T11: Rs 4 Fuel surcharge, PAN India on chargeable weight (IndiGo footnotes) | U11: Fuel ₹4
A12: AMD|JAI|6E7261|15:40 | B12: AMD | C12: JAI | D12: INDIGO | E12: 6E7261 | F12: 15:40 | G12: GCR | H12: 46250 | I12: 1800 | J12: 64 | K12: 52 | L12: 45 | P12: OK | R12: Route rate (all flights) | S12: 4 | T12: Rs 4 Fuel surcharge, PAN India on chargeable weight (IndiGo footnotes) | U12: Fuel ₹4
A13: AMD|JAI|6E7131|21:05 | B13: AMD | C13: JAI | D13: INDIGO | E13: 6E7131 | F13: 21:05 | G13: GCR | H13: 46250 | I13: 1800 | J13: 64 | K13: 52 | L13: 45 | P13: OK | R13: Route rate (all flights) | S13: 4 | T13: Rs 4 Fuel surcharge, PAN India on chargeable weight (IndiGo footnotes) | U13: Fuel ₹4
A14: AMD|LKO|6E6244|08:15 | B14: AMD | C14: LKO | D14: INDIGO | E14: 6E6244 | F14: 08:15 | G14: GCR | H14: 46250 | I14: 1800 | J14: 64 | K14: 52 | L14: 45 | P14: OK | R14: Route rate (all flights) | S14: 4 | T14: Rs 4 Fuel surcharge, PAN India on chargeable weight (IndiGo footnotes) | U14: Fuel ₹4
A15: AMD|LKO|6E935|14:15 | B15: AMD | C15: LKO | D15: INDIGO | E15: 6E935 | F15: 14:15 | G15: GCR | H15: 46250 | I15: 1800 | J15: 64 | K15: 52 | L15: 45 | P15: OK | R15: Route rate (all flights) | S15: 4 | T15: Rs 4 Fuel surcharge, PAN India on chargeable weight (IndiGo footnotes) | U15: Fuel ₹4
A16: AMD|NAG|6E7247|05:40 | B16: AMD | C16: NAG | D16: INDIGO | E16: 6E7247 | F16: 05:40 | G16: GCR | H16: 46250 | I16: 1800 | J16: 60 | K16: 48 | L16: 41 | P16: OK | R16: Route rate (all flights) | S16: 4 | T16: Rs 4 Fuel surcharge, PAN India on chargeable weight (IndiGo footnotes) | U16: Fuel ₹4
A17: AMD|NAG|6E7502|18:55 | B17: AMD | C17: NAG | D17: INDIGO | E17: 6E7502 | F17: 18:55 | G17: GCR | H17: 46250 | I17: 1800 | J17: 60 | K17: 48 | L17: 41 | P17: OK | R17: Route rate (all flights) | S17: 4 | T17: Rs 4 Fuel surcharge, PAN India on chargeable weight (IndiGo footnotes) | U17: Fuel ₹4
A18: AMD|PAT|6E921|10:40 | B18: AMD | C18: PAT | D18: INDIGO | E18: 6E921 | F18: 10:40 | G18: GCR | H18: 46250 | I18: 1800 | J18: 65 | K18: 53 | L18: 46 | P18: OK | R18: Route rate (all flights) | S18: 4 | T18: Rs 4 Fuel surcharge, PAN India on chargeable weight (IndiGo footnotes) | U18: Fuel ₹4
A19: AMD|PAT|6E2524|18:30 | B19: AMD | C19: PAT | D19: INDIGO | E19: 6E2524 | F19: 18:30 | G19: GCR | H19: 46250 | I19: 1800 | J19: 65 | K19: 53 | L19: 46 | P19: OK | R19: Route rate (all flights) | S19: 4 | T19: Rs 4 Fuel surcharge, PAN India on chargeable weight (IndiGo footnotes) | U19: Fuel ₹4
A20: AMD|IXR|6E6493|11:10 | B20: AMD | C20: IXR | D20: INDIGO | E20: 6E6493 | F20: 11:10 | G20: GCR | H20: 46250 | I20: 1800 | J20: 68 | K20: 54 | L20: 47 | P20: OK | R20: Route rate (all flights) | S20: 9 | T20: Rs 5 IndiGo sector surcharge; Rs 4 Fuel surcharge, PAN India on chargeable weight (IndiGo footnotes) | U20: Sector ₹5 + Fuel ₹4
A21: AMD|RPR|6E261|11:30 | B21: AMD | C21: RPR | D21: INDIGO | E21: 6E261 | F21: 11:30 | G21: GCR | H21: 46250 | I21: 1800 | J21: 64 | K21: 52 | L21: 45 | P21: OK | R21: Route rate (all flights) | S21: 4 | T21: Rs 4 Fuel surcharge, PAN India on chargeable weight (IndiGo footnotes) | U21: Fuel ₹4
A22: AMD|IXC|6E6375|07:40 | B22: AMD | C22: IXC | D22: INDIGO | E22: 6E6375 | F22: 07:40 | G22: GCR | H22: 46250 | I22: 1800 | J22: 68 | K22: 54 | L22: 47 | P22: OK | R22: Route rate (all flights) | S22: 4 | T22: Rs 4 Fuel surcharge, PAN India on chargeable weight (IndiGo footnotes) | U22: Fuel ₹4
... A28: AMD|VNS|6E6805|14:45 | B28: AMD | C28: VNS | D28: INDIGO | E28: 6E6805 | F28: 14:45 | G28: GCR | H28: 46250 | I28: 1800 | J28: 68 | K28: 54 | L28: 47 | P28: OK | R28: Route rate (all flights) | S28: 4 | T28: Rs 4 Fuel surcharge, PAN India on chargeable weight (IndiGo footnotes) | U28: Fuel ₹4
A29: BLR|BBI|6E702|07:30 | B29: BLR | C29: BBI | D29: INDIGO | E29: 6E702 | F29: 07:30 | G29: GCR | H29: 46250 | I29: 1800 | J29: 71 | K29: 56 | L29: 45 | M29: 42 | P29: OK | R29: Route rate (all flights) | S29: 4 | T29: Rs 4 Fuel surcharge, PAN India on chargeable weight (IndiGo footnotes) | U29: Fuel ₹4
A30: BLR|BBI|6E6535|11:40 | B30: BLR | C30: BBI | D30: INDIGO | E30: 6E6535 | F30: 11:40 | G30: GCR | H30: 46250 | I30: 1800 | J30: 71 | K30: 56 | L30: 45 | M30: 42 | P30: OK | R30: Route rate (all flights) | S30: 4 | T30: Rs 4 Fuel surcharge, PAN India on chargeable weight (IndiGo footnotes) | U30: Fuel ₹4
A31: BLR|BBI|6E411|20:05 | B31: BLR | C31: BBI | D31: INDIGO | E31: 6E411 | F31: 20:05 | G31: GCR | H31: 46250 | I31: 1800 | J31: 71 | K31: 56 | L31: 45 | M31: 42 | P31: OK | R31: Route rate (all flights) | S31: 4 | T31: Rs 4 Fuel surcharge, PAN India on chargeable weight (IndiGo footnotes) | U31: Fuel ₹4
A32: BLR|BBI|QP1503|13:35 | B32: BLR | C32: BBI | D32: AKASA | E32: QP1503 | F32: 13:35 | P32: NO TARIFF LOADED | R32: This airline's tariff is not loaded in the database
